Workbook

Sheet Config
A1: ⚙️ SWING TRADE CONFIG — Investors Way
A3: Parameter | B3: Value | C3: Notes
A4: Total Capital (₹) | B4: 500000 | C4: Apna total trading capital daal
A5: Max Risk per Trade (%) | B5: 2 | C5: 1-2% recommended — zyada mat karo
A6: Max Open Positions | B6: 4 | C6: Ek time pe kitne trades max
A7: Brokerage per Order (₹) | B7: 20 | C7: Zerodha flat ₹20
A8: Min R:R Ratio | B8: 2 | C8: 2:1 se kam = skip
A10: 📊 DERIVED (auto-calculated)
A11: Risk Amount per Trade (₹) | B11: =B4*B5/100
A12: Capital per Position (₹) | B12: =B4/B6
A13: Telegram Bot Token | B13: 8627084548:AAEpQXg8Ff3WBSYwh8s2DcdE_WWiwr_c_WM
A14: Telegram Chat ID | B14: 8215983641

Sheet Trade Log
A1: Date | B1: Stock | C1: Entry Price (₹) | D1: SL Price (₹) | E1: Target 1 (₹) | F1: Target 2 (₹) | G1: SL % | H1: R:R (T1) | I1: R:R (T2) | J1: Signal | K1: Qty | L1: Position Size (₹) | M1: Risk Amt (₹) | N1: GTT SL Trigger | O1: GTT SL Price | P1: GTT Target Trigger | Q1: GTT Target Price | R1: Status | S1: Exit Price (₹) | T1: P&L (₹) | U1: P&L % | V1: Notes
A2: 2026-07-18 | B2: FEDERALBNK | C2: 349 | D2: 333.41 | E2: 364.59 | F2: 380.18 | G2: 0.0447 | H2: 1 | I2: 2 | J2: GO | K2: 19 | L2: 6631 | M2: 300 | N2: 333.74 | O2: 333.41 | P2: 379.8 | Q2: 380.18 | R2: CLOSED - SL | S2: 333.41 | T2: =IF(AND(S2<>"",K2<>""),(S2-C2)*K2-2*Config!B7,"") | U2: =IF(AND(T2<>"",L2<>""),T2/L2*100,"")
A3: 2026-07-18 | B3: MBAPL | C3: 136.2 | D3: 122.76 | E3: 149.64 | F3: 163.07 | G3: 0.0986 | H3: 1 | I3: 2 | J3: GO | K3: 22 | L3: 2996.4 | M3: 300 | N3: 122.88 | O3: 122.76 | P3: 162.91 | Q3: 163.07 | R3: OPEN | T3: =IF(AND(S3<>"",K3<>""),(S3-C3)*K3-2*Config!B7,"") | U3: =IF(AND(T3<>"",L3<>""),T3/L3*100,"")
A4: 2026-07-18 | B4: SONACOMS | C4: 704.85 | D4: 669.46 | E4: 740.24 | F4: 775.62 | G4: 0.0502 | H4: 1 | I4: 2 | J4: GO | K4: 8 | L4: 5638.8 | M4: 300 | N4: 670.13 | O4: 669.46 | P4: 774.84 | Q4: 775.62 | R4: OPEN | T4: =IF(AND(S4<>"",K4<>""),(S4-C4)*K4-2*Config!B7,"") | U4: =IF(AND(T4<>"",L4<>""),T4/L4*100,"")
A5: 2026-07-18 | B5: ABB | C5: 7506 | D5: 7050.63 | E5: 7961.37 | F5: 8416.74 | G5: 0.0607 | H5: 1 | I5: 2 | J5: SKIP | K5: 0 | L5: 0 | M5: 300 | N5: 7057.68 | O5: 7050.63 | P5: 8408.32 | Q5: 8416.74 | R5: OPEN | T5: =IF(AND(S5<>"",K5<>""),(S5-C5)*K5-2*Config!B7,"") | U5: =IF(AND(T5<>"",L5<>""),T5/L5*100,"")
A6: 2026-07-18 | B6: APOLLOHOSP | C6: 8826 | D6: 8554.78 | E6: 9097.22 | F6: 9368.44 | G6: 0.0307 | H6: 1 | I6: 2 | J6: GO | K6: 1 | L6: 8826 | M6: 300 | N6: 8563.33 | O6: 8554.78 | P6: 9359.07 | Q6: 9368.44 | R6: OPEN | T6: =IF(AND(S6<>"",K6<>""),(S6-C6)*K6-2*Config!B7,"") | U6: =IF(AND(T6<>"",L6<>""),T6/L6*100,"")
A7: 2026-07-20 | B7: FEDERALBNK | C7: 350.75 | D7: 334.75 | E7: 366.75 | F7: 382.76 | G7: 0.0456 | H7: 1 | I7: 2 | J7: GO | K7: 625 | L7: 219218.75 | M7: 10000 | N7: 335.08 | O7: 334.75 | P7: 382.38 | Q7: 382.76 | V7: Financial Services
T8: =IF(AND(S8<>"",K8<>""),(S8-C8)*K8-2*Config!B7,"") | U8: =IF(AND(T8<>"",L8<>""),T8/L8*100,"")
T9: =IF(AND(S9<>"",K9<>""),(S9-C9)*K9-2*Config!B7,"") | U9: =IF(AND(T9<>"",L9<>""),T9/L9*100,"")
T10: =IF(AND(S10<>"",K10<>""),(S10-C10)*K10-2*Config!B7,"") | U10: =IF(AND(T10<>"",L10<>""),T10/L10*100,"")
T11: =IF(AND(S11<>"",K11<>""),(S11-C11)*K11-2*Config!B7,"") | U11: =IF(AND(T11<>"",L11<>""),T11/L11*100,"")
T12: =IF(AND(S12<>"",K12<>""),(S12-C12)*K12-2*Config!B7,"") | U12: =IF(AND(T12<>"",L12<>""),T12/L12*100,"")
T13: =IF(AND(S13<>"",K13<>""),(S13-C13)*K13-2*Config!B7,"") | U13: =IF(AND(T13<>"",L13<>""),T13/L13*100,"")
T14: =IF(AND(S14<>"",K14<>""),(S14-C14)*K14-2*Config!B7,"") | U14: =IF(AND(T14<>"",L14<>""),T14/L14*100,"")
T15: =IF(AND(S15<>"",K15<>""),(S15-C15)*K15-2*Config!B7,"") | U15: =IF(AND(T15<>"",L15<>""),T15/L15*100,"")
T16: =IF(AND(S16<>"",K16<>""),(S16-C16)*K16-2*Config!B7,"") | U16: =IF(AND(T16<>"",L16<>""),T16/L16*100,"")
T17: =IF(AND(S17<>"",K17<>""),(S17-C17)*K17-2*Config!B7,"") | U17: =IF(AND(T17<>"",L17<>""),T17/L17*100,"")
T18: =IF(AND(S18<>"",K18<>""),(S18-C18)*K18-2*Config!B7,"") | U18: =IF(AND(T18<>"",L18<>""),T18/L18*100,"")
T19: =IF(AND(S19<>"",K19<>""),(S19-C19)*K19-2*Config!B7,"") | U19: =IF(AND(T19<>"",L19<>""),T19/L19*100,"")
T20: =IF(AND(S20<>"",K20<>""),(S20-C20)*K20-2*Config!B7,"") | U20: =IF(AND(T20<>"",L20<>""),T20/L20*100,"")
T21: =IF(AND(S21<>"",K21<>""),(S21-C21)*K21-2*Config!B7,"") | U21: =IF(AND(T21<>"",L21<>""),T21/L21*100,"")
T22: =IF(AND(S22<>"",K22<>""),(S22-C22)*K22-2*Config!B7,"") | U22: =IF(AND(T22<>"",L22<>""),T22/L22*100,"")
T23: =IF(AND(S23<>"",K23<>""),(S23-C23)*K23-2*Config!B7,"") | U23: =IF(AND(T23<>"",L23<>""),T23/L23*100,"")
T24: =IF(AND(S24<>"",K24<>""),(S24-C24)*K24-2*Config!B7,"") | U24: =IF(AND(T24<>"",L24<>""),T24/L24*100,"")
T25: =IF(AND(S25<>"",K25<>""),(S25-C25)*K25-2*Config!B7,"") | U25: =IF(AND(T25<>"",L25<>""),T25/L25*100,"")
T26: =IF(AND(S26<>"",K26<>""),(S26-C26)*K26-2*Config!B7,"") | U26: =IF(AND(T26<>"",L26<>""),T26/L26*100,"")
T27: =IF(AND(S27<>"",K27<>""),(S27-C27)*K27-2*Config!B7,"") | U27: =IF(AND(T27<>"",L27<>""),T27/L27*100,"")
T28: =IF(AND(S28<>"",K28<>""),(S28-C28)*K28-2*Config!B7,"") | U28: =IF(AND(T28<>"",L28<>""),T28/L28*100,"")
T29: =IF(AND(S29<>"",K29<>""),(S29-C29)*K29-2*Config!B7,"") | U29: =IF(AND(T29<>"",L29<>""),T29/L29*100,"")
T30: =IF(AND(S30<>"",K30<>""),(S30-C30)*K30-2*Config!B7,"") | U30: =IF(AND(T30<>"",L30<>""),T30/L30*100,"")
T31: =IF(AND(S31<>"",K31<>""),(S31-C31)*K31-2*Config!B7,"") | U31: =IF(AND(T31<>"",L31<>""),T31/L31*100,"")
T32: =IF(AND(S32<>"",K32<>""),(S32-C32)*K32-2*Config!B7,"") | U32: =IF(AND(T32<>"",L32<>""),T32/L32*100,"")
T33: =IF(AND(S33<>"",K33<>""),(S33-C33)*K33-2*Config!B7,"") | U33: =IF(AND(T33<>"",L33<>""),T33/L33*100,"")
T34: =IF(AND(S34<>"",K34<>""),(S34-C34)*K34-2*Config!B7,"") | U34: =IF(AND(T34<>"",L34<>""),T34/L34*100,"")
T35: =IF(AND(S35<>"",K35<>""),(S35-C35)*K35-2*Config!B7,"") | U35: =IF(AND(T35<>"",L35<>""),T35/L35*100,"")
T36: =IF(AND(S36<>"",K36<>""),(S36-C36)*K36-2*Config!B7,"") | U36: =IF(AND(T36<>"",L36<>""),T36/L36*100,"")
T37: =IF(AND(S37<>"",K37<>""),(S37-C37)*K37-2*Config!B7,"") | U37: =IF(AND(T37<>"",L37<>""),T37/L37*100,"")
T38: =IF(AND(S38<>"",K38<>""),(S38-C38)*K38-2*Config!B7,"") | U38: =IF(AND(T38<>"",L38<>""),T38/L38*100,"")
T39: =IF(AND(S39<>"",K39<>""),(S39-C39)*K39-2*Config!B7,"") | U39: =IF(AND(T39<>"",L39<>""),T39/L39*100,"")
T40: =IF(AND(S40<>"",K40<>""),(S40-C40)*K40-2*Config!B7,"") | U40: =IF(AND(T40<>"",L40<>""),T40/L40*100,"")
...

Sheet Dashboard
A1: 📊 TRADE PERFORMANCE DASHBOARD
A3: Total Trades Taken | B3: =COUNTA('Trade Log'!B2:B51)
A4: Winning Trades | B4: =COUNTIF('Trade Log'!T2:T51,">"&0)
A5: Losing Trades | B5: =COUNTIF('Trade Log'!T2:T51,"<"&0)
A6: Win Rate (%) | B6: =IF(B3>0,B4/B3*100,0)
A7: Total P&L (₹) | B7: =SUMIF('Trade Log'!T2:T51,"<>"&"",'Trade Log'!T2:T51)
A8: Avg Win (₹) | B8: =IF(B4>0,SUMIF('Trade Log'!T2:T51,">"&0,'Trade Log'!T2:T51)/B4,0)
A9: Avg Loss (₹) | B9: =IF(B5>0,SUMIF('Trade Log'!T2:T51,"<"&0,'Trade Log'!T2:T51)/B5,0)
A10: Expectancy (₹) | B10: =IF(B3>0,B7/B3,0)
A11: Largest Win (₹) | B11: =IF(B3>0,MAX('Trade Log'!T2:T51),0)
A12: Largest Loss (₹) | B12: =IF(B3>0,MIN('Trade Log'!T2:T51),0)
A13: Capital Deployed (₹) | B13: =SUMIF('Trade Log'!L2:L51,"<>"&"",'Trade Log'!L2:L51)
A14: ROI on Deployed (%) | B14: =IF(B13>0,B7/B13*100,0)

Sheet How To Use
A1: WORKFLOW — Pine Script → Sheet → Zerodha GTT
A3: STEP 1: Config sheet mein apna capital, risk %, max positions set karo (blue cells = editable)
A4: STEP 2: TradingView pe Pine Script indicator se Entry, SL, T1, T2 note karo
A5: STEP 3: Trade Log mein Date, Stock, Entry, SL, T1, T2 bharo — baaki auto-fill hoga
A6: STEP 4: Signal column dekho — ✅ GO = trade lo, ❌ SKIP = chhodo
A7: STEP 5: GTT columns (N-Q) se direct Zerodha mein OCO order place karo:
A8: → GTT SL Trigger (col N) = Zerodha GTT mein 'Stoploss Trigger'
A9: → GTT SL Price (col O) = 'Stoploss Limit Price' (0.5% buffer included)
A10: → GTT Target Trigger (col P) = 'Target Trigger'
A11: → GTT Target Price (col Q) = 'Target Limit Price' (0.2% buffer included)
A12: STEP 6: Trade exit ke baad Status (OPEN/SL HIT/TARGET/PARTIAL) aur Exit Price bharo
A13: STEP 7: Dashboard sheet pe apna overall performance track karo
... A20: • P&L mein ₹40 brokerage (entry+exit) already deducted hai

Sheet Watchlist
A1: Date | B1: Stock | C1: LTP (₹) | D1: 52W High (₹) | E1: % from High | F1: SMA50 | G1: 1M Return % | H1: Note
A2: 2026-07-20 | B2: FLUOROCHEM | C2: 4316.2 | D2: 4329.2 | E2: 0.3 | F2: 3805.69 | G2: 12.4 | H2: Near-breakout — watch for volume surge + close above high
A3: 2026-07-20 | B3: SUNPHARMA | C3: 1956.4 | D3: 1962.7 | E3: 0.32 | F3: 1854.4 | G3: 6.7 | H3: Near-breakout — watch for volume surge + close above high
A4: 2026-07-20 | B4: ADOR | C4: 1455.3 | D4: 1460 | E4: 0.32 | F4: 1174.88 | G4: 21.69 | H4: Near-breakout — watch for volume surge + close above high
A5: 2026-07-20 | B5: LLOYDSME | C5: 1907.9 | D5: 1914.8 | E5: 0.36 | F5: 1771.15 | G5: 8.02 | H5: Near-breakout — watch for volume surge + close above high
A6: 2026-07-20 | B6: NAVINFLUOR | C6: 7861.5 | D6: 7900 | E6: 0.49 | F6: 7327.15 | G6: 4.91 | H6: Near-breakout — watch for volume surge + close above high
A7: 2026-07-20 | B7: SONACOMS | C7: 714.55 | D7: 718.65 | E7: 0.57 | F7: 619.25 | G7: 16.75 | H7: Near-breakout — watch for volume surge + close above high
A8: 2026-07-20 | B8: SAREGAMA | C8: 514.15 | D8: 518.55 | E8: 0.85 | F8: 451.1 | G8: 10.36 | H8: Near-breakout — watch for volume surge + close above high
A9: 2026-07-20 | B9: KABRAEXTRU | C9: 351.65 | D9: 355 | E9: 0.94 | F9: 254.26 | G9: 47.91 | H9: Near-breakout — watch for volume surge + close above high
A10: 2026-07-20 | B10: SHREEJISPG | C10: 615.85 | D10: 621.9 | E10: 0.97 | F10: 487.37 | G10: 23.02 | H10: Near-breakout — watch for volume surge + close above high
A11: 2026-07-20 | B11: CYIENTDLM | C11: 596.05 | D11: 602.95 | E11: 1.14 | F11: 468.33 | G11: 25.84 | H11: Near-breakout — watch for volume surge + close above high
A12: 2026-07-20 | B12: APOLLOHOSP | C12: 8905 | D12: 9009 | E12: 1.15 | F12: 8473.21 | G12: 4.89 | H12: Near-breakout — watch for volume surge + close above high
A13: 2026-07-20 | B13: GANDHAR | C13: 228.32 | D13: 231 | E13: 1.16 | F13: 172.79 | G13: 26.66 | H13: Near-breakout — watch for volume surge + close above high
... A35: 2026-07-20 | B35: STYRENIX | C35: 2365.1 | D35: 3132.62 | E35: 24.5 | F35: 2259.9 | G35: 2.26 | H35: Near-breakout — watch for volume surge + close above high
